[32m2024-02-05 13:29:06 +0100[0m - dagster - [34mDEBUG[0m - __ASSET_JOB - 7f8fe53a-2086-4622-8638-d73b72fd8914 - 55513 - LOGS_CAPTURED - Started capturing logs in process (pid: 55513).
[32m2024-02-05 13:29:06 +0100[0m - dagster - [34mDEBUG[0m - __ASSET_JOB - 7f8fe53a-2086-4622-8638-d73b72fd8914 - 55513 - chunk_blog_content - STEP_START - Started execution of step "chunk_blog_content".
[32m2024-02-05 13:29:06 +0100[0m - dagster - [34mDEBUG[0m - __ASSET_JOB - 7f8fe53a-2086-4622-8638-d73b72fd8914 - chunk_blog_content - Loading file from: /Users/szymonzmyslony/projects/master-pipeline/pipeline/.dagster/storage/fetched_blog_content using PickledObjectFilesystemIOManager...
[32m2024-02-05 13:29:06 +0100[0m - dagster - [34mDEBUG[0m - __ASSET_JOB - 7f8fe53a-2086-4622-8638-d73b72fd8914 - 55513 - chunk_blog_content - ASSET_OBSERVATION - DagsterEventType.ASSET_OBSERVATION for step chunk_blog_content
[32m2024-02-05 13:29:06 +0100[0m - dagster - [34mDEBUG[0m - __ASSET_JOB - 7f8fe53a-2086-4622-8638-d73b72fd8914 - 55513 - chunk_blog_content - LOADED_INPUT - Loaded input "fetched_blog_content" using input manager "io_manager"
[32m2024-02-05 13:29:06 +0100[0m - dagster - [34mDEBUG[0m - __ASSET_JOB - 7f8fe53a-2086-4622-8638-d73b72fd8914 - 55513 - chunk_blog_content - STEP_INPUT - Got input "fetched_blog_content" of type "Any". (Type check passed).
[32m2024-02-05 13:29:06 +0100[0m - dagster - [34mERROR[0m - [31m__ASSET_JOB - 7f8fe53a-2086-4622-8638-d73b72fd8914 - 55513 - chunk_blog_content - STEP_FAILURE - Execution of step "chunk_blog_content" failed.

dagster._core.errors.DagsterInvalidMetadata: Could not resolve the metadata value for "first" to a known type. Value is not JSON serializable.

Stack Trace:
  File "/Users/szymonzmyslony/Library/Caches/pypoetry/virtualenvs/pipeline-RtkjAAJa-py3.11/lib/python3.11/site-packages/dagster/_core/execution/plan/execute_plan.py", line 286, in dagster_event_sequence_for_step
    for step_event in check.generator(step_events):
  File "/Users/szymonzmyslony/Library/Caches/pypoetry/virtualenvs/pipeline-RtkjAAJa-py3.11/lib/python3.11/site-packages/dagster/_core/execution/plan/execute_step.py", line 487, in core_dagster_event_sequence_for_step
    for user_event in _step_output_error_checked_user_event_sequence(
  File "/Users/szymonzmyslony/Library/Caches/pypoetry/virtualenvs/pipeline-RtkjAAJa-py3.11/lib/python3.11/site-packages/dagster/_core/execution/plan/execute_step.py", line 245, in _step_output_error_checked_user_event_sequence
    **normalize_metadata(metadata or {}),
      ^^^^^^^^^^^^^^^^^^^^^^^^^^^^^^^^^^
  File "/Users/szymonzmyslony/Library/Caches/pypoetry/virtualenvs/pipeline-RtkjAAJa-py3.11/lib/python3.11/site-packages/dagster/_core/definitions/metadata/__init__.py", line 98, in normalize_metadata
    raise DagsterInvalidMetadata(

The above exception occurred during handling of the following exception:
dagster._core.errors.DagsterInvalidMetadata: Value is not JSON serializable.

Stack Trace:
  File "/Users/szymonzmyslony/Library/Caches/pypoetry/virtualenvs/pipeline-RtkjAAJa-py3.11/lib/python3.11/site-packages/dagster/_core/definitions/metadata/__init__.py", line 84, in normalize_metadata
    normalized_value = normalize_metadata_value(v)
                       ^^^^^^^^^^^^^^^^^^^^^^^^^^^
  File "/Users/szymonzmyslony/Library/Caches/pypoetry/virtualenvs/pipeline-RtkjAAJa-py3.11/lib/python3.11/site-packages/dagster/_core/definitions/metadata/__init__.py", line 120, in normalize_metadata_value
    return MetadataValue.json(raw_value)
           ^^^^^^^^^^^^^^^^^^^^^^^^^^^^^
  File "/Users/szymonzmyslony/Library/Caches/pypoetry/virtualenvs/pipeline-RtkjAAJa-py3.11/lib/python3.11/site-packages/dagster/_core/definitions/metadata/__init__.py", line 283, in json
    return JsonMetadataValue(data)
           ^^^^^^^^^^^^^^^^^^^^^^^
  File "/Users/szymonzmyslony/Library/Caches/pypoetry/virtualenvs/pipeline-RtkjAAJa-py3.11/lib/python3.11/site-packages/dagster/_core/definitions/metadata/__init__.py", line 690, in __new__
    raise DagsterInvalidMetadata("Value is not JSON serializable.")

The above exception occurred during handling of the following exception:
TypeError: Object of type SemanticSection is not JSON serializable

Stack Trace:
  File "/Users/szymonzmyslony/Library/Caches/pypoetry/virtualenvs/pipeline-RtkjAAJa-py3.11/lib/python3.11/site-packages/dagster/_core/definitions/metadata/__init__.py", line 688, in __new__
    seven.dumps(data)
  File "/nix/store/03q8gn91mj95y5bqbcl90hyvmpqpz738-python3-3.11.7/lib/python3.11/json/__init__.py", line 238, in dumps
    **kw).encode(obj)
          ^^^^^^^^^^^
  File "/nix/store/03q8gn91mj95y5bqbcl90hyvmpqpz738-python3-3.11.7/lib/python3.11/json/encoder.py", line 200, in encode
    chunks = self.iterencode(o, _one_shot=True)
             ^^^^^^^^^^^^^^^^^^^^^^^^^^^^^^^^^^
  File "/nix/store/03q8gn91mj95y5bqbcl90hyvmpqpz738-python3-3.11.7/lib/python3.11/json/encoder.py", line 258, in iterencode
    return _iterencode(o, 0)
           ^^^^^^^^^^^^^^^^^
  File "/nix/store/03q8gn91mj95y5bqbcl90hyvmpqpz738-python3-3.11.7/lib/python3.11/json/encoder.py", line 180, in default
    raise TypeError(f'Object of type {o.__class__.__name__} '
[0m
