[32m2024-02-05 21:16:06 +0100[0m - dagster - [34mDEBUG[0m - __ASSET_JOB - 807a2786-d627-4e0a-b08c-637a9230b4fd - 92811 - LOGS_CAPTURED - Started capturing logs in process (pid: 92811).
[32m2024-02-05 21:16:06 +0100[0m - dagster - [34mDEBUG[0m - __ASSET_JOB - 807a2786-d627-4e0a-b08c-637a9230b4fd - 92811 - combined_and_cleaned_video_docs - STEP_START - Started execution of step "combined_and_cleaned_video_docs".
[32m2024-02-05 21:16:06 +0100[0m - dagster - [34mDEBUG[0m - __ASSET_JOB - 807a2786-d627-4e0a-b08c-637a9230b4fd - combined_and_cleaned_video_docs - Loading file from: /Users/szymonzmyslony/projects/master-pipeline/pipeline/.dagster/storage/complete_video_content using PickledObjectFilesystemIOManager...
[32m2024-02-05 21:16:06 +0100[0m - dagster - [34mDEBUG[0m - __ASSET_JOB - 807a2786-d627-4e0a-b08c-637a9230b4fd - 92811 - combined_and_cleaned_video_docs - ASSET_OBSERVATION - DagsterEventType.ASSET_OBSERVATION for step combined_and_cleaned_video_docs
[32m2024-02-05 21:16:06 +0100[0m - dagster - [34mDEBUG[0m - __ASSET_JOB - 807a2786-d627-4e0a-b08c-637a9230b4fd - 92811 - combined_and_cleaned_video_docs - LOADED_INPUT - Loaded input "complete_video_content" using input manager "io_manager"
[32m2024-02-05 21:16:06 +0100[0m - dagster - [34mDEBUG[0m - __ASSET_JOB - 807a2786-d627-4e0a-b08c-637a9230b4fd - 92811 - combined_and_cleaned_video_docs - STEP_INPUT - Got input "complete_video_content" of type "Any". (Type check passed).
[32m2024-02-05 21:16:06 +0100[0m - dagster - [34mINFO[0m - __ASSET_JOB - 807a2786-d627-4e0a-b08c-637a9230b4fd - combined_and_cleaned_video_docs - https://www.ycombinator.com/library/GV-should-you-start-a-startup
[32m2024-02-05 21:16:06 +0100[0m - dagster - [34mINFO[0m - __ASSET_JOB - 807a2786-d627-4e0a-b08c-637a9230b4fd - combined_and_cleaned_video_docs - Has returned md secitons False paragraphs from the document.
[32m2024-02-05 21:16:06 +0100[0m - dagster - [34mINFO[0m - __ASSET_JOB - 807a2786-d627-4e0a-b08c-637a9230b4fd - combined_and_cleaned_video_docs - Going into emedding mode
[32m2024-02-05 21:16:12 +0100[0m - dagster - [34mINFO[0m - __ASSET_JOB - 807a2786-d627-4e0a-b08c-637a9230b4fd - combined_and_cleaned_video_docs - Generated 9 chunks from 27 paragraphs.
[32m2024-02-05 21:16:12 +0100[0m - dagster - [34mINFO[0m - __ASSET_JOB - 807a2786-d627-4e0a-b08c-637a9230b4fd - combined_and_cleaned_video_docs - https://www.ycombinator.com/library/6q-how-to-pitch-your-startup
[32m2024-02-05 21:16:12 +0100[0m - dagster - [34mINFO[0m - __ASSET_JOB - 807a2786-d627-4e0a-b08c-637a9230b4fd - combined_and_cleaned_video_docs - Has returned md secitons False paragraphs from the document.
[32m2024-02-05 21:16:12 +0100[0m - dagster - [34mINFO[0m - __ASSET_JOB - 807a2786-d627-4e0a-b08c-637a9230b4fd - combined_and_cleaned_video_docs - Going into emedding mode
[32m2024-02-05 21:16:24 +0100[0m - dagster - [34mINFO[0m - __ASSET_JOB - 807a2786-d627-4e0a-b08c-637a9230b4fd - combined_and_cleaned_video_docs - Generated 16 chunks from 90 paragraphs.
[32m2024-02-05 21:16:24 +0100[0m - dagster - [34mINFO[0m - __ASSET_JOB - 807a2786-d627-4e0a-b08c-637a9230b4fd - combined_and_cleaned_video_docs - https://www.ycombinator.com/library/J0-inside-the-group-partner-lounge-when-to-launch-your-startup
[32m2024-02-05 21:16:24 +0100[0m - dagster - [34mINFO[0m - __ASSET_JOB - 807a2786-d627-4e0a-b08c-637a9230b4fd - combined_and_cleaned_video_docs - Has returned md secitons False paragraphs from the document.
[32m2024-02-05 21:16:24 +0100[0m - dagster - [34mINFO[0m - __ASSET_JOB - 807a2786-d627-4e0a-b08c-637a9230b4fd - combined_and_cleaned_video_docs - Going into emedding mode
[32m2024-02-05 21:17:13 +0100[0m - dagster - [34mINFO[0m - __ASSET_JOB - 807a2786-d627-4e0a-b08c-637a9230b4fd - combined_and_cleaned_video_docs - Generated 10 chunks from 388 paragraphs.
[32m2024-02-05 21:17:13 +0100[0m - dagster - [34mINFO[0m - __ASSET_JOB - 807a2786-d627-4e0a-b08c-637a9230b4fd - combined_and_cleaned_video_docs - https://www.ycombinator.com/library/Jq-garry-s-channel-should-you-be-the-ceo
[32m2024-02-05 21:17:13 +0100[0m - dagster - [34mINFO[0m - __ASSET_JOB - 807a2786-d627-4e0a-b08c-637a9230b4fd - combined_and_cleaned_video_docs - Has returned md secitons False paragraphs from the document.
[32m2024-02-05 21:17:13 +0100[0m - dagster - [34mINFO[0m - __ASSET_JOB - 807a2786-d627-4e0a-b08c-637a9230b4fd - combined_and_cleaned_video_docs - Going into emedding mode
[32m2024-02-05 21:17:19 +0100[0m - dagster - [34mINFO[0m - __ASSET_JOB - 807a2786-d627-4e0a-b08c-637a9230b4fd - combined_and_cleaned_video_docs - Generated 7 chunks from 230 paragraphs.
[32m2024-02-05 21:17:19 +0100[0m - dagster - [34mINFO[0m - __ASSET_JOB - 807a2786-d627-4e0a-b08c-637a9230b4fd - combined_and_cleaned_video_docs - https://www.ycombinator.com/library/8h-how-to-find-the-right-co-founder
[32m2024-02-05 21:17:19 +0100[0m - dagster - [34mINFO[0m - __ASSET_JOB - 807a2786-d627-4e0a-b08c-637a9230b4fd - combined_and_cleaned_video_docs - Has returned md secitons False paragraphs from the document.
[32m2024-02-05 21:17:19 +0100[0m - dagster - [34mINFO[0m - __ASSET_JOB - 807a2786-d627-4e0a-b08c-637a9230b4fd - combined_and_cleaned_video_docs - Going into emedding mode
[32m2024-02-05 21:17:21 +0100[0m - dagster - [34mINFO[0m - __ASSET_JOB - 807a2786-d627-4e0a-b08c-637a9230b4fd - combined_and_cleaned_video_docs - Generated 14 chunks from 32 paragraphs.
[32m2024-02-05 21:17:21 +0100[0m - dagster - [34mINFO[0m - __ASSET_JOB - 807a2786-d627-4e0a-b08c-637a9230b4fd - combined_and_cleaned_video_docs - https://www.ycombinator.com/library/8H-analytics-for-startups
[32m2024-02-05 21:17:21 +0100[0m - dagster - [34mINFO[0m - __ASSET_JOB - 807a2786-d627-4e0a-b08c-637a9230b4fd - combined_and_cleaned_video_docs - Has returned md secitons False paragraphs from the document.
[32m2024-02-05 21:17:21 +0100[0m - dagster - [34mINFO[0m - __ASSET_JOB - 807a2786-d627-4e0a-b08c-637a9230b4fd - combined_and_cleaned_video_docs - Going into emedding mode
[32m2024-02-05 21:17:24 +0100[0m - dagster - [34mINFO[0m - __ASSET_JOB - 807a2786-d627-4e0a-b08c-637a9230b4fd - combined_and_cleaned_video_docs - Generated 17 chunks from 600 paragraphs.
[32m2024-02-05 21:17:24 +0100[0m - dagster - [34mINFO[0m - __ASSET_JOB - 807a2786-d627-4e0a-b08c-637a9230b4fd - combined_and_cleaned_video_docs - https://www.ycombinator.com/library/DY-dalton-michael-yc-founders-made-these-fundraising-mistakes
[32m2024-02-05 21:17:24 +0100[0m - dagster - [34mINFO[0m - __ASSET_JOB - 807a2786-d627-4e0a-b08c-637a9230b4fd - combined_and_cleaned_video_docs - Has returned md secitons False paragraphs from the document.
[32m2024-02-05 21:17:24 +0100[0m - dagster - [34mINFO[0m - __ASSET_JOB - 807a2786-d627-4e0a-b08c-637a9230b4fd - combined_and_cleaned_video_docs - Going into emedding mode
[32m2024-02-05 21:17:26 +0100[0m - dagster - [34mINFO[0m - __ASSET_JOB - 807a2786-d627-4e0a-b08c-637a9230b4fd - combined_and_cleaned_video_docs - Generated 7 chunks from 223 paragraphs.
[32m2024-02-05 21:17:26 +0100[0m - dagster - [34mINFO[0m - __ASSET_JOB - 807a2786-d627-4e0a-b08c-637a9230b4fd - combined_and_cleaned_video_docs - https://www.ycombinator.com/library/AQ-how-to-pick-which-startup-to-work-at
[32m2024-02-05 21:17:26 +0100[0m - dagster - [34mINFO[0m - __ASSET_JOB - 807a2786-d627-4e0a-b08c-637a9230b4fd - combined_and_cleaned_video_docs - Has returned md secitons False paragraphs from the document.
[32m2024-02-05 21:17:26 +0100[0m - dagster - [34mINFO[0m - __ASSET_JOB - 807a2786-d627-4e0a-b08c-637a9230b4fd - combined_and_cleaned_video_docs - Going into emedding mode
[32m2024-02-05 21:29:06 +0100[0m - dagster - [34mERROR[0m - [31m__ASSET_JOB - 807a2786-d627-4e0a-b08c-637a9230b4fd - 92811 - combined_and_cleaned_video_docs - STEP_FAILURE - Execution of step "combined_and_cleaned_video_docs" failed.

dagster._core.errors.DagsterExecutionStepExecutionError: Error occurred while executing op "combined_and_cleaned_video_docs"::

openai.APITimeoutError: Request timed out.

Stack Trace:
  File "/Users/szymonzmyslony/Library/Caches/pypoetry/virtualenvs/pipeline-RtkjAAJa-py3.11/lib/python3.11/site-packages/dagster/_core/execution/plan/utils.py", line 54, in op_execution_error_boundary
    yield
  File "/Users/szymonzmyslony/Library/Caches/pypoetry/virtualenvs/pipeline-RtkjAAJa-py3.11/lib/python3.11/site-packages/dagster/_utils/__init__.py", line 467, in iterate_with_context
    next_output = next(iterator)
                  ^^^^^^^^^^^^^^
  File "/Users/szymonzmyslony/Library/Caches/pypoetry/virtualenvs/pipeline-RtkjAAJa-py3.11/lib/python3.11/site-packages/dagster/_core/execution/plan/compute_generator.py", line 131, in _coerce_op_compute_fn_to_iterator
    result = invoke_compute_fn(
             ^^^^^^^^^^^^^^^^^^
  File "/Users/szymonzmyslony/Library/Caches/pypoetry/virtualenvs/pipeline-RtkjAAJa-py3.11/lib/python3.11/site-packages/dagster/_core/execution/plan/compute_generator.py", line 125, in invoke_compute_fn
    return fn(context, **args_to_pass) if context_arg_provided else fn(**args_to_pass)
           ^^^^^^^^^^^^^^^^^^^^^^^^^^^
  File "/Users/szymonzmyslony/projects/master-pipeline/pipeline/pipeline/assets.py", line 282, in combined_and_cleaned_video_docs
    cleaned_documents = [
                        ^
  File "/Users/szymonzmyslony/projects/master-pipeline/pipeline/pipeline/assets.py", line 287, in <listcomp>
    chunk_document(video)
  File "/Users/szymonzmyslony/projects/master-pipeline/pipeline/pipeline/assets.py", line 278, in chunk_document
    chunks, title = transcript_chunker.chunk_document()
                    ^^^^^^^^^^^^^^^^^^^^^^^^^^^^^^^^^^^
  File "/Users/szymonzmyslony/projects/master-pipeline/pipeline/chunker/DocumentChunker.py", line 143, in chunk_document
    self.embed_paragraphs()
  File "/Users/szymonzmyslony/projects/master-pipeline/pipeline/chunker/DocumentChunker.py", line 77, in embed_paragraphs
    batch_embeddings = [x.embedding for x in get_embedding(batch)]
                                             ^^^^^^^^^^^^^^^^^^^^
  File "/Users/szymonzmyslony/projects/master-pipeline/pipeline/chunker/embeddings.py", line 15, in get_embedding
    response = client.embeddings.create(input=text, model=model)
               ^^^^^^^^^^^^^^^^^^^^^^^^^^^^^^^^^^^^^^^^^^^^^^^^^
  File "/Users/szymonzmyslony/Library/Caches/pypoetry/virtualenvs/pipeline-RtkjAAJa-py3.11/lib/python3.11/site-packages/openai/resources/embeddings.py", line 113, in create
    return self._post(
           ^^^^^^^^^^^
  File "/Users/szymonzmyslony/Library/Caches/pypoetry/virtualenvs/pipeline-RtkjAAJa-py3.11/lib/python3.11/site-packages/openai/_base_client.py", line 1200, in post
    return cast(ResponseT, self.request(cast_to, opts, stream=stream, stream_cls=stream_cls))
                           ^^^^^^^^^^^^^^^^^^^^^^^^^^^^^^^^^^^^^^^^^^^^^^^^^^^^^^^^^^^^^^^^^
  File "/Users/szymonzmyslony/Library/Caches/pypoetry/virtualenvs/pipeline-RtkjAAJa-py3.11/lib/python3.11/site-packages/openai/_base_client.py", line 889, in request
    return self._request(
           ^^^^^^^^^^^^^^
  File "/Users/szymonzmyslony/Library/Caches/pypoetry/virtualenvs/pipeline-RtkjAAJa-py3.11/lib/python3.11/site-packages/openai/_base_client.py", line 927, in _request
    return self._retry_request(
           ^^^^^^^^^^^^^^^^^^^^
  File "/Users/szymonzmyslony/Library/Caches/pypoetry/virtualenvs/pipeline-RtkjAAJa-py3.11/lib/python3.11/site-packages/openai/_base_client.py", line 1013, in _retry_request
    return self._request(
           ^^^^^^^^^^^^^^
  File "/Users/szymonzmyslony/Library/Caches/pypoetry/virtualenvs/pipeline-RtkjAAJa-py3.11/lib/python3.11/site-packages/openai/_base_client.py", line 927, in _request
    return self._retry_request(
           ^^^^^^^^^^^^^^^^^^^^
  File "/Users/szymonzmyslony/Library/Caches/pypoetry/virtualenvs/pipeline-RtkjAAJa-py3.11/lib/python3.11/site-packages/openai/_base_client.py", line 1013, in _retry_request
    return self._request(
           ^^^^^^^^^^^^^^
  File "/Users/szymonzmyslony/Library/Caches/pypoetry/virtualenvs/pipeline-RtkjAAJa-py3.11/lib/python3.11/site-packages/openai/_base_client.py", line 937, in _request
    raise APITimeoutError(request=request) from err

The above exception was caused by the following exception:
httpx.ConnectTimeout: timed out

Stack Trace:
  File "/Users/szymonzmyslony/Library/Caches/pypoetry/virtualenvs/pipeline-RtkjAAJa-py3.11/lib/python3.11/site-packages/openai/_base_client.py", line 918, in _request
    response = self._client.send(
               ^^^^^^^^^^^^^^^^^^
  File "/Users/szymonzmyslony/Library/Caches/pypoetry/virtualenvs/pipeline-RtkjAAJa-py3.11/lib/python3.11/site-packages/httpx/_client.py", line 915, in send
    response = self._send_handling_auth(
               ^^^^^^^^^^^^^^^^^^^^^^^^^
  File "/Users/szymonzmyslony/Library/Caches/pypoetry/virtualenvs/pipeline-RtkjAAJa-py3.11/lib/python3.11/site-packages/httpx/_client.py", line 943, in _send_handling_auth
    response = self._send_handling_redirects(
               ^^^^^^^^^^^^^^^^^^^^^^^^^^^^^^
  File "/Users/szymonzmyslony/Library/Caches/pypoetry/virtualenvs/pipeline-RtkjAAJa-py3.11/lib/python3.11/site-packages/httpx/_client.py", line 980, in _send_handling_redirects
    response = self._send_single_request(request)
               ^^^^^^^^^^^^^^^^^^^^^^^^^^^^^^^^^^
  File "/Users/szymonzmyslony/Library/Caches/pypoetry/virtualenvs/pipeline-RtkjAAJa-py3.11/lib/python3.11/site-packages/httpx/_client.py", line 1016, in _send_single_request
    response = transport.handle_request(request)
               ^^^^^^^^^^^^^^^^^^^^^^^^^^^^^^^^^
  File "/Users/szymonzmyslony/Library/Caches/pypoetry/virtualenvs/pipeline-RtkjAAJa-py3.11/lib/python3.11/site-packages/httpx/_transports/default.py", line 230, in handle_request
    with map_httpcore_exceptions():
  File "/nix/store/03q8gn91mj95y5bqbcl90hyvmpqpz738-python3-3.11.7/lib/python3.11/contextlib.py", line 158, in __exit__
    self.gen.throw(typ, value, traceback)
  File "/Users/szymonzmyslony/Library/Caches/pypoetry/virtualenvs/pipeline-RtkjAAJa-py3.11/lib/python3.11/site-packages/httpx/_transports/default.py", line 84, in map_httpcore_exceptions
    raise mapped_exc(message) from exc

The above exception was caused by the following exception:
httpcore.ConnectTimeout: timed out

Stack Trace:
  File "/Users/szymonzmyslony/Library/Caches/pypoetry/virtualenvs/pipeline-RtkjAAJa-py3.11/lib/python3.11/site-packages/httpx/_transports/default.py", line 67, in map_httpcore_exceptions
    yield
  File "/Users/szymonzmyslony/Library/Caches/pypoetry/virtualenvs/pipeline-RtkjAAJa-py3.11/lib/python3.11/site-packages/httpx/_transports/default.py", line 231, in handle_request
    resp = self._pool.handle_request(req)
           ^^^^^^^^^^^^^^^^^^^^^^^^^^^^^^
  File "/Users/szymonzmyslony/Library/Caches/pypoetry/virtualenvs/pipeline-RtkjAAJa-py3.11/lib/python3.11/site-packages/httpcore/_sync/connection_pool.py", line 268, in handle_request
    raise exc
  File "/Users/szymonzmyslony/Library/Caches/pypoetry/virtualenvs/pipeline-RtkjAAJa-py3.11/lib/python3.11/site-packages/httpcore/_sync/connection_pool.py", line 251, in handle_request
    response = connection.handle_request(request)
               ^^^^^^^^^^^^^^^^^^^^^^^^^^^^^^^^^^
  File "/Users/szymonzmyslony/Library/Caches/pypoetry/virtualenvs/pipeline-RtkjAAJa-py3.11/lib/python3.11/site-packages/httpcore/_sync/connection.py", line 99, in handle_request
    raise exc
  File "/Users/szymonzmyslony/Library/Caches/pypoetry/virtualenvs/pipeline-RtkjAAJa-py3.11/lib/python3.11/site-packages/httpcore/_sync/connection.py", line 76, in handle_request
    stream = self._connect(request)
             ^^^^^^^^^^^^^^^^^^^^^^
  File "/Users/szymonzmyslony/Library/Caches/pypoetry/virtualenvs/pipeline-RtkjAAJa-py3.11/lib/python3.11/site-packages/httpcore/_sync/connection.py", line 124, in _connect
    stream = self._network_backend.connect_tcp(**kwargs)
             ^^^^^^^^^^^^^^^^^^^^^^^^^^^^^^^^^^^^^^^^^^^
  File "/Users/szymonzmyslony/Library/Caches/pypoetry/virtualenvs/pipeline-RtkjAAJa-py3.11/lib/python3.11/site-packages/httpcore/_backends/sync.py", line 205, in connect_tcp
    with map_exceptions(exc_map):
  File "/nix/store/03q8gn91mj95y5bqbcl90hyvmpqpz738-python3-3.11.7/lib/python3.11/contextlib.py", line 158, in __exit__
    self.gen.throw(typ, value, traceback)
  File "/Users/szymonzmyslony/Library/Caches/pypoetry/virtualenvs/pipeline-RtkjAAJa-py3.11/lib/python3.11/site-packages/httpcore/_exceptions.py", line 14, in map_exceptions
    raise to_exc(exc) from exc

The above exception was caused by the following exception:
TimeoutError: timed out

Stack Trace:
  File "/Users/szymonzmyslony/Library/Caches/pypoetry/virtualenvs/pipeline-RtkjAAJa-py3.11/lib/python3.11/site-packages/httpcore/_exceptions.py", line 10, in map_exceptions
    yield
  File "/Users/szymonzmyslony/Library/Caches/pypoetry/virtualenvs/pipeline-RtkjAAJa-py3.11/lib/python3.11/site-packages/httpcore/_backends/sync.py", line 206, in connect_tcp
    sock = socket.create_connection(
           ^^^^^^^^^^^^^^^^^^^^^^^^^
  File "/nix/store/03q8gn91mj95y5bqbcl90hyvmpqpz738-python3-3.11.7/lib/python3.11/socket.py", line 851, in create_connection
    raise exceptions[0]
  File "/nix/store/03q8gn91mj95y5bqbcl90hyvmpqpz738-python3-3.11.7/lib/python3.11/socket.py", line 836, in create_connection
    sock.connect(sa)

The above exception occurred during handling of the following exception:
httpx.ConnectTimeout: _ssl.c:989: The handshake operation timed out

Stack Trace:
  File "/Users/szymonzmyslony/Library/Caches/pypoetry/virtualenvs/pipeline-RtkjAAJa-py3.11/lib/python3.11/site-packages/openai/_base_client.py", line 918, in _request
    response = self._client.send(
               ^^^^^^^^^^^^^^^^^^
  File "/Users/szymonzmyslony/Library/Caches/pypoetry/virtualenvs/pipeline-RtkjAAJa-py3.11/lib/python3.11/site-packages/httpx/_client.py", line 915, in send
    response = self._send_handling_auth(
               ^^^^^^^^^^^^^^^^^^^^^^^^^
  File "/Users/szymonzmyslony/Library/Caches/pypoetry/virtualenvs/pipeline-RtkjAAJa-py3.11/lib/python3.11/site-packages/httpx/_client.py", line 943, in _send_handling_auth
    response = self._send_handling_redirects(
               ^^^^^^^^^^^^^^^^^^^^^^^^^^^^^^
  File "/Users/szymonzmyslony/Library/Caches/pypoetry/virtualenvs/pipeline-RtkjAAJa-py3.11/lib/python3.11/site-packages/httpx/_client.py", line 980, in _send_handling_redirects
    response = self._send_single_request(request)
               ^^^^^^^^^^^^^^^^^^^^^^^^^^^^^^^^^^
  File "/Users/szymonzmyslony/Library/Caches/pypoetry/virtualenvs/pipeline-RtkjAAJa-py3.11/lib/python3.11/site-packages/httpx/_client.py", line 1016, in _send_single_request
    response = transport.handle_request(request)
               ^^^^^^^^^^^^^^^^^^^^^^^^^^^^^^^^^
  File "/Users/szymonzmyslony/Library/Caches/pypoetry/virtualenvs/pipeline-RtkjAAJa-py3.11/lib/python3.11/site-packages/httpx/_transports/default.py", line 230, in handle_request
    with map_httpcore_exceptions():
  File "/nix/store/03q8gn91mj95y5bqbcl90hyvmpqpz738-python3-3.11.7/lib/python3.11/contextlib.py", line 158, in __exit__
    self.gen.throw(typ, value, traceback)
  File "/Users/szymonzmyslony/Library/Caches/pypoetry/virtualenvs/pipeline-RtkjAAJa-py3.11/lib/python3.11/site-packages/httpx/_transports/default.py", line 84, in map_httpcore_exceptions
    raise mapped_exc(message) from exc

The above exception was caused by the following exception:
httpcore.ConnectTimeout: _ssl.c:989: The handshake operation timed out

Stack Trace:
  File "/Users/szymonzmyslony/Library/Caches/pypoetry/virtualenvs/pipeline-RtkjAAJa-py3.11/lib/python3.11/site-packages/httpx/_transports/default.py", line 67, in map_httpcore_exceptions
    yield
  File "/Users/szymonzmyslony/Library/Caches/pypoetry/virtualenvs/pipeline-RtkjAAJa-py3.11/lib/python3.11/site-packages/httpx/_transports/default.py", line 231, in handle_request
    resp = self._pool.handle_request(req)
           ^^^^^^^^^^^^^^^^^^^^^^^^^^^^^^
  File "/Users/szymonzmyslony/Library/Caches/pypoetry/virtualenvs/pipeline-RtkjAAJa-py3.11/lib/python3.11/site-packages/httpcore/_sync/connection_pool.py", line 268, in handle_request
    raise exc
  File "/Users/szymonzmyslony/Library/Caches/pypoetry/virtualenvs/pipeline-RtkjAAJa-py3.11/lib/python3.11/site-packages/httpcore/_sync/connection_pool.py", line 251, in handle_request
    response = connection.handle_request(request)
               ^^^^^^^^^^^^^^^^^^^^^^^^^^^^^^^^^^
  File "/Users/szymonzmyslony/Library/Caches/pypoetry/virtualenvs/pipeline-RtkjAAJa-py3.11/lib/python3.11/site-packages/httpcore/_sync/connection.py", line 99, in handle_request
    raise exc
  File "/Users/szymonzmyslony/Library/Caches/pypoetry/virtualenvs/pipeline-RtkjAAJa-py3.11/lib/python3.11/site-packages/httpcore/_sync/connection.py", line 76, in handle_request
    stream = self._connect(request)
             ^^^^^^^^^^^^^^^^^^^^^^
  File "/Users/szymonzmyslony/Library/Caches/pypoetry/virtualenvs/pipeline-RtkjAAJa-py3.11/lib/python3.11/site-packages/httpcore/_sync/connection.py", line 156, in _connect
    stream = stream.start_tls(**kwargs)
             ^^^^^^^^^^^^^^^^^^^^^^^^^^
  File "/Users/szymonzmyslony/Library/Caches/pypoetry/virtualenvs/pipeline-RtkjAAJa-py3.11/lib/python3.11/site-packages/httpcore/_backends/sync.py", line 152, in start_tls
    with map_exceptions(exc_map):
  File "/nix/store/03q8gn91mj95y5bqbcl90hyvmpqpz738-python3-3.11.7/lib/python3.11/contextlib.py", line 158, in __exit__
    self.gen.throw(typ, value, traceback)
  File "/Users/szymonzmyslony/Library/Caches/pypoetry/virtualenvs/pipeline-RtkjAAJa-py3.11/lib/python3.11/site-packages/httpcore/_exceptions.py", line 14, in map_exceptions
    raise to_exc(exc) from exc

The above exception was caused by the following exception:
TimeoutError: _ssl.c:989: The handshake operation timed out

Stack Trace:
  File "/Users/szymonzmyslony/Library/Caches/pypoetry/virtualenvs/pipeline-RtkjAAJa-py3.11/lib/python3.11/site-packages/httpcore/_exceptions.py", line 10, in map_exceptions
    yield
  File "/Users/szymonzmyslony/Library/Caches/pypoetry/virtualenvs/pipeline-RtkjAAJa-py3.11/lib/python3.11/site-packages/httpcore/_backends/sync.py", line 168, in start_tls
    raise exc
  File "/Users/szymonzmyslony/Library/Caches/pypoetry/virtualenvs/pipeline-RtkjAAJa-py3.11/lib/python3.11/site-packages/httpcore/_backends/sync.py", line 163, in start_tls
    sock = ssl_context.wrap_socket(
           ^^^^^^^^^^^^^^^^^^^^^^^^
  File "/nix/store/03q8gn91mj95y5bqbcl90hyvmpqpz738-python3-3.11.7/lib/python3.11/ssl.py", line 517, in wrap_socket
    return self.sslsocket_class._create(
           ^^^^^^^^^^^^^^^^^^^^^^^^^^^^^
  File "/nix/store/03q8gn91mj95y5bqbcl90hyvmpqpz738-python3-3.11.7/lib/python3.11/ssl.py", line 1108, in _create
    self.do_handshake()
  File "/nix/store/03q8gn91mj95y5bqbcl90hyvmpqpz738-python3-3.11.7/lib/python3.11/ssl.py", line 1383, in do_handshake
    self._sslobj.do_handshake()

The above exception occurred during handling of the following exception:
httpx.ReadTimeout: The read operation timed out

Stack Trace:
  File "/Users/szymonzmyslony/Library/Caches/pypoetry/virtualenvs/pipeline-RtkjAAJa-py3.11/lib/python3.11/site-packages/openai/_base_client.py", line 918, in _request
    response = self._client.send(
               ^^^^^^^^^^^^^^^^^^
  File "/Users/szymonzmyslony/Library/Caches/pypoetry/virtualenvs/pipeline-RtkjAAJa-py3.11/lib/python3.11/site-packages/httpx/_client.py", line 929, in send
    raise exc
  File "/Users/szymonzmyslony/Library/Caches/pypoetry/virtualenvs/pipeline-RtkjAAJa-py3.11/lib/python3.11/site-packages/httpx/_client.py", line 923, in send
    response.read()
  File "/Users/szymonzmyslony/Library/Caches/pypoetry/virtualenvs/pipeline-RtkjAAJa-py3.11/lib/python3.11/site-packages/httpx/_models.py", line 811, in read
    self._content = b"".join(self.iter_bytes())
                    ^^^^^^^^^^^^^^^^^^^^^^^^^^^
  File "/Users/szymonzmyslony/Library/Caches/pypoetry/virtualenvs/pipeline-RtkjAAJa-py3.11/lib/python3.11/site-packages/httpx/_models.py", line 829, in iter_bytes
    for raw_bytes in self.iter_raw():
  File "/Users/szymonzmyslony/Library/Caches/pypoetry/virtualenvs/pipeline-RtkjAAJa-py3.11/lib/python3.11/site-packages/httpx/_models.py", line 887, in iter_raw
    for raw_stream_bytes in self.stream:
  File "/Users/szymonzmyslony/Library/Caches/pypoetry/virtualenvs/pipeline-RtkjAAJa-py3.11/lib/python3.11/site-packages/httpx/_client.py", line 124, in __iter__
    for chunk in self._stream:
  File "/Users/szymonzmyslony/Library/Caches/pypoetry/virtualenvs/pipeline-RtkjAAJa-py3.11/lib/python3.11/site-packages/httpx/_transports/default.py", line 110, in __iter__
    with map_httpcore_exceptions():
  File "/nix/store/03q8gn91mj95y5bqbcl90hyvmpqpz738-python3-3.11.7/lib/python3.11/contextlib.py", line 158, in __exit__
    self.gen.throw(typ, value, traceback)
  File "/Users/szymonzmyslony/Library/Caches/pypoetry/virtualenvs/pipeline-RtkjAAJa-py3.11/lib/python3.11/site-packages/httpx/_transports/default.py", line 84, in map_httpcore_exceptions
    raise mapped_exc(message) from exc

The above exception was caused by the following exception:
httpcore.ReadTimeout: The read operation timed out

Stack Trace:
  File "/Users/szymonzmyslony/Library/Caches/pypoetry/virtualenvs/pipeline-RtkjAAJa-py3.11/lib/python3.11/site-packages/httpx/_transports/default.py", line 67, in map_httpcore_exceptions
    yield
  File "/Users/szymonzmyslony/Library/Caches/pypoetry/virtualenvs/pipeline-RtkjAAJa-py3.11/lib/python3.11/site-packages/httpx/_transports/default.py", line 111, in __iter__
    for part in self._httpcore_stream:
  File "/Users/szymonzmyslony/Library/Caches/pypoetry/virtualenvs/pipeline-RtkjAAJa-py3.11/lib/python3.11/site-packages/httpcore/_sync/connection_pool.py", line 361, in __iter__
    for part in self._stream:
  File "/Users/szymonzmyslony/Library/Caches/pypoetry/virtualenvs/pipeline-RtkjAAJa-py3.11/lib/python3.11/site-packages/httpcore/_sync/http11.py", line 337, in __iter__
    raise exc
  File "/Users/szymonzmyslony/Library/Caches/pypoetry/virtualenvs/pipeline-RtkjAAJa-py3.11/lib/python3.11/site-packages/httpcore/_sync/http11.py", line 329, in __iter__
    for chunk in self._connection._receive_response_body(**kwargs):
  File "/Users/szymonzmyslony/Library/Caches/pypoetry/virtualenvs/pipeline-RtkjAAJa-py3.11/lib/python3.11/site-packages/httpcore/_sync/http11.py", line 198, in _receive_response_body
    event = self._receive_event(timeout=timeout)
            ^^^^^^^^^^^^^^^^^^^^^^^^^^^^^^^^^^^^
  File "/Users/szymonzmyslony/Library/Caches/pypoetry/virtualenvs/pipeline-RtkjAAJa-py3.11/lib/python3.11/site-packages/httpcore/_sync/http11.py", line 212, in _receive_event
    data = self._network_stream.read(
           ^^^^^^^^^^^^^^^^^^^^^^^^^^
  File "/Users/szymonzmyslony/Library/Caches/pypoetry/virtualenvs/pipeline-RtkjAAJa-py3.11/lib/python3.11/site-packages/httpcore/_backends/sync.py", line 124, in read
    with map_exceptions(exc_map):
  File "/nix/store/03q8gn91mj95y5bqbcl90hyvmpqpz738-python3-3.11.7/lib/python3.11/contextlib.py", line 158, in __exit__
    self.gen.throw(typ, value, traceback)
  File "/Users/szymonzmyslony/Library/Caches/pypoetry/virtualenvs/pipeline-RtkjAAJa-py3.11/lib/python3.11/site-packages/httpcore/_exceptions.py", line 14, in map_exceptions
    raise to_exc(exc) from exc

The above exception was caused by the following exception:
TimeoutError: The read operation timed out

Stack Trace:
  File "/Users/szymonzmyslony/Library/Caches/pypoetry/virtualenvs/pipeline-RtkjAAJa-py3.11/lib/python3.11/site-packages/httpcore/_exceptions.py", line 10, in map_exceptions
    yield
  File "/Users/szymonzmyslony/Library/Caches/pypoetry/virtualenvs/pipeline-RtkjAAJa-py3.11/lib/python3.11/site-packages/httpcore/_backends/sync.py", line 126, in read
    return self._sock.recv(max_bytes)
           ^^^^^^^^^^^^^^^^^^^^^^^^^^
  File "/nix/store/03q8gn91mj95y5bqbcl90hyvmpqpz738-python3-3.11.7/lib/python3.11/ssl.py", line 1296, in recv
    return self.read(buflen)
           ^^^^^^^^^^^^^^^^^
  File "/nix/store/03q8gn91mj95y5bqbcl90hyvmpqpz738-python3-3.11.7/lib/python3.11/ssl.py", line 1169, in read
    return self._sslobj.read(len)
           ^^^^^^^^^^^^^^^^^^^^^^
[0m
